Workbook

Sheet BP
A1: Ano | B1: Grupo | C1: Subgrupo | D1: Conta | E1: Valor
A2: 2022 | B2: Ativo | C2: Total | D2: Total do Ativo | E2: 2029399
A3: 2022 | B3: Ativo | C3: Conta Redutora do Ativo | D3: (Provisões para Perdas Associadas ao Risco de Crédito) | E3: -54048
A4: 2022 | B4: Ativo | C4: Total | D4: Total do Ativo Circulante | E4: =SUM(E5:E7,E3) -> 1956514
A5: 2022 | B5: Ativo | C5: Ativo Circulante | D5: Disponibilidades | E5: 18311
A6: 2022 | B6: Ativo | C6: Ativo Circulante | D6: Ativos Financeiros | E6: 1925433
A7: 2022 | B7: Ativo | C7: Ativo Circulante | D7: Ativos Fiscais | E7: 66818
A8: 2022 | B8: Ativo | C8: Total | D8: Total do Ativo Não Circulante | E8: =SUM(E9:E12) -> 72886
A9: 2022 | B9: Ativo | C9: Ativo Não Circulante | D9: Investimentos | E9: 18794
A10: 2022 | B10: Ativo | C10: Ativo Não Circulante | D10: Imobilizado de Uso | E10: 8826
A11: 2022 | B11: Ativo | C11: Ativo Não Circulante | D11: Intangível | E11: 11091
A12: 2022 | B12: Ativo | C12: Ativo Não Circulante | D12: Outros Ativos Não Financeiros | E12: 34175
A13: 2022 | B13: Passivo | C13: Total | D13: Total do Passivo | E13: 1865370
A14: 2022 | B14: Passivo | C14: Total | D14: Total do Passivo Circulante | E14: =SUM(E15:E18) -> 1865370
A15: 2022 | B15: Passivo | C15: Passivo Circulante | D15: Passivos Financeiros | E15: 1782027
A16: 2022 | B16: Passivo | C16: Passivo Circulante | D16: Provisões | E16: 25718
A17: 2022 | B17: Passivo | C17: Passivo Circulante | D17: Passivos Fiscais | E17: 20973
A18: 2022 | B18: Passivo | C18: Passivo Circulante | D18: Outros Passivos Não Financeiros | E18: 36652
A19: 2022 | B19: Patrimônio Líquido | C19: Total | D19: Patrimônio Líquido | E19: 164029
A20: 2022 | B20: Patrimônio Líquido | C20: Capital | D20: Capital | E20: 90000
A21: 2022 | B21: Patrimônio Líquido | C21: Capital | D21: Instrumento Elegível ao Capital Principal | E21: 7100
A22: 2022 | B22: Patrimônio Líquido | C22: Reservas | D22: Reservas de Capital | E22: 1404
A23: 2022 | B23: Patrimônio Líquido | C23: Reservas | D23: Reservas de Lucros | E23: 70142
A24: 2022 | B24: Patrimônio Líquido | C24: Ajustes | D24: Outros Resultados Abrangentes | E24: -8225
A25: 2022 | B25: Patrimônio Líquido | C25: Conta Redutora do PL | D25: (Ações em Tesouraria) | E25: -273
A26: 2022 | B26: Patrimônio Líquido | C26: Resultados | D26: Lucros ou Prejuízos Acumulados | E26: 422
... A29: 2023 | B29: Ativo | C29: Conta Redutora do Ativo | D29: (Provisões para Perdas Associadas ao Risco de Crédito) | E29: -59673
A30: 2023 | B30: Ativo | C30: Total | D30: Total do Ativo Circulante | E30: =SUM(E31:E33,E29) -> 2100841
A31: 2023 | B31: Ativo | C31: Ativo Circulante | D31: Disponibilidades | E31: 17328
A32: 2023 | B32: Ativo | C32: Ativo Circulante | D32: Ativos Financeiros | E32: 2072861
A33: 2023 | B33: Ativo | C33: Ativo Circulante | D33: Ativos Fiscais | E33: 70325
A34: 2023 | B34: Ativo | C34: Total | D34: Total do Ativo Não Circulante | E34: =SUM(E35:E38) -> 71639
A35: 2023 | B35: Ativo | C35: Ativo Não Circulante | D35: Investimentos | E35: 21082
A36: 2023 | B36: Ativo | C36: Ativo Não Circulante | D36: Imobilizado de Uso | E36: 10072
A37: 2023 | B37: Ativo | C37: Ativo Não Circulante | D37: Intangível | E37: 10801
A38: 2023 | B38: Ativo | C38: Ativo Não Circulante | D38: Outros Ativos Não Financeiros | E38: 29684
A39: 2023 | B39: Passivo | C39: Total | D39: Total do Passivo | E39: 1999403
A40: 2023 | B40: Passivo | C40: Total | D40: Total do Passivo Circulante | E40: =SUM(E41:E44) -> 1999403
A41: 2023 | B41: Passivo | C41: Passivo Circulante | D41: Passivos Financeiros | E41: 1911665
A42: 2023 | B42: Passivo | C42: Passivo Circulante | D42: Provisões | E42: 26748
...

Sheet DRE
A1: Ano | B1: Conta | C1: Valor
A2: 2022 | B2: Resultado da Intermediação Financeira | C2: 62966
A3: 2022 | B3: Receitas de Prestação de Serviços | C3: 32333
A4: 2022 | B4: Receita Total | C4: =SUM(C2:C3) -> 95299
A5: 2022 | B5: Resultado Operacional | C5: 48559
A6: 2022 | B6: Resultado Antes da Trib. s/ o Lucro | C6: 48700
A7: 2022 | B7: Imposto de Renda e Contribuição Social | C7: 10195
A8: 2022 | B8: Lucro Líquido | C8: 31011
A9: 2023 | B9: Resultado da Intermediação Financeira | C9: 56650
A10: 2023 | B10: Receitas de Prestação de Serviços | C10: 33831
A11: 2023 | B11: Receita Total | C11: =SUM(C9:C10) -> 90481
A12: 2023 | B12: Resultado Operacional | C12: 52002
A13: 2023 | B13: Resultado Antes da Trib. s/ o Lucro | C13: 52255
A14: 2023 | B14: Imposto de Renda e Contribuição Social | C14: 8382
A15: 2023 | B15: Lucro Líquido | C15: 33819
A16: 2024 | B16: Resultado da Intermediação Financeira | C16: 66796
A17: 2024 | B17: Receitas de Prestação de Serviços | C17: 35477
A18: 2024 | B18: Receita Total | C18: =SUM(C16:C17) -> 102273
A19: 2024 | B19: Resultado Operacional | C19: 46731
A20: 2024 | B20: Resultado Antes da Trib. s/ o Lucro | C20: 47005
A21: 2024 | B21: Imposto de Renda e Contribuição Social | C21: 3371
A22: 2024 | B22: Lucro Líquido | C22: 35439
A24: Nota: no ano de 2022 e 2023 não existe resultado da intermediação financeira, então foi utilizada a margem financeira líquida, que é o também retira os detalhamentos de provisão e é utilizada para cálculos analíticos. Foi inserida uma proxy no lugar nos anos 22 e 23.

Sheet Indicadores
A1: Ano | B1: Referência | C1: Indicador | D1: Fórmula | E1: Valor | F1: Significado | G1: Interpretação
A2: 2022 | B2: BP | C2: Liquidez Imediata | D2: Disponibilidades/PC | E2: =(BP!E5/BP!E14) -> 0.0098162831 | F2: verifica a disponibilidade financeira existente no caixa ou no banco para pagamento das dívidas de curto prazo | G2: quanto maior, melhor
A3: 2022 | B3: BP | C3: Liquidez Geral | D3: (AC+ANC)/(PC+PNC) | E3: =SUM(BP!E4,BP!E8)/SUM(BP!E14) -> 1.0879343 | F3: verifica a capacidade financeira da empresa no curto e no longo prazo. | G3: quanto maior, melhor
A4: 2022 | B4: BP | C4: Liquidez Corrente ou Comum | D4: AC/PC | E4: =BP!E4/BP!E14 -> 1.0488611 | F4: verifica a capacidade financeira da empresa no curto prazo | G4: quanto maior, melhor
A5: 2022 | B5: BP | C5: Grau de Endividamento | D5: (PC+PNC)/PL | E5: =BP!E14/BP!E19 -> 11.372196 | F5: representa a relação entre o capital próprio e o capital de terceiros, ou seja, revela o quanto a empresa depende de recursos de terceiros, e isso pode influenciar diretamente na liberdade de decisão dos proprietários | G5: quanto menor, melhor
A6: 2022 | B6: BP | C6: Composição do Endividamento | D6: PC/(PC+PNC) | E6: =BP!E14/BP!E13 -> 1 | F6: através dessa análise é possível mensurar o volume de dívidas da empresa no curto prazo em relação à dívida total | G6: quanto menor, melhor
A7: 2022 | B7: BP | C7: Imobilização do Patrimônio Líquido | D7: Ativo Imobilizado/PL | E7: =BP!E10/BP!E19 -> 0.053807558 | F7: quanto mais a empresa imobiliza o seu capital próprio, mais ela dependerá de capitais de terceiros. Esse indicador mostra o volume de capital circulante próprio | G7: quanto menor, melhor
A8: 2022 | B8: DRE | C8: Giro do Ativo | D8: Receita Líquida/Ativo Total | E8: =DRE!C4/BP!E2 -> 0.046959223 | F8: estabelece a relação entre as vendas do período e os investimentos totais efetuados na empresa, expressando o nível de eficiência com que são utilizados os recursos aplicados, ou seja, a produtividade dos investimentos totais | G8: quanto maior, melhor
A9: 2022 | B9: DRE | C9: Margem Líquida | D9: Lucro Líquido/Receita Líquida | E9: =DRE!C8/DRE!C4 -> 0.3254074 | F9: Também conhecido como retorno sobre as vendas, apresenta o percentual de lucratividade gerado | G9: quanto maior, melhor
A10: 2022 | B10: DRE | C10: Rentabilidade ou Retorno do Ativo (ROA ou ROI) | D10: Lucro Líquido/Ativo Total | E10: =DRE!C8/BP!E2 -> 0.015280879 | F10: mede a eficiência global da alta administração na geração de lucros com seus investimentos | G10: quanto maior, melhor
A11: 2022 | B11: DRE | C11: Rentabilidade do Patrimônio Líquido ou Retorno do Capital Próprio | D11: Lucro Líquido/Patrimônio Líquido | E11: =DRE!C8/BP!E19 -> 0.18905803 | F11: apresenta o retorno que os acionistas ou quotistas da empresa estão obtendo em relação aos investimentos na empresa, ficando patente o prêmio do investidor ou proprietário pelo risco de seu empreendimento quando o indicador (taxa) obtido é superior à taxa média de juros do mercado | G11: quanto maior, melhor
A12: 2022 | B12: DRE | C12: Grau de Alavancagem Financeira | D12: Rentabilidade do Patrimônio Líquido/Rentabilidade do Ativo | E12: =E11/E10 -> 12.372196 | F12: avalia a capacidade da empresa em utilizar encargos financeiros fixos para maximizar os efeitos da variação do lucro. Determina o grau de impacto nos resultados decorrentes da utilização de capitais de terceiros | G12: quanto maior, melhor
A13: 2023 | B13: BP | C13: Liquidez Imediata | D13: Disponibilidades/PC | E13: =BP!E31/BP!E40 -> 0.008666587 | F13: verifica a disponibilidade financeira existente no caixa ou no banco para pagamento das dívidas de curto prazo | G13: quanto maior, melhor
A14: 2023 | B14: BP | C14: Liquidez Geral | D14: (AC+ANC)/(PC+PNC) | E14: =SUM(BP!E30,BP!E34)/BP!E40 -> 1.0865643 | F14: verifica a capacidade financeira da empresa no curto e no longo prazo. | G14: quanto maior, melhor
A15: 2023 | B15: BP | C15: Liquidez Corrente ou Comum | D15: AC/PC | E15: =BP!E30/BP!E40 -> 1.0507341 | F15: verifica a capacidade financeira da empresa no curto prazo | G15: quanto maior, melhor
A16: 2023 | B16: BP | C16: Grau de Endividamento | D16: (PC+PNC)/PL | E16: =BP!E39/BP!E45 -> 11.552168 | F16: representa a relação entre o capital próprio e o capital de terceiros, ou seja, revela o quanto a empresa depende de recursos de terceiros, e isso pode influenciar diretamente na liberdade de decisão dos proprietários | G16: quanto menor, melhor
A17: 2023 | B17: BP | C17: Composição do Endividamento | D17: PC/(PC+PNC) | E17: =BP!E40/BP!E39 -> 1 | F17: através dessa análise é possível mensurar o volume de dívidas da empresa no curto prazo em relação à dívida total | G17: quanto menor, melhor
A18: 2023 | B18: BP | C18: Imobilização do Patrimônio Líquido | D18: Ativo Imobilizado/PL | E18: =BP!E36/BP!E45 -> 0.058194088 | F18: quanto mais a empresa imobiliza o seu capital próprio, mais ela dependerá de capitais de terceiros. Esse indicador mostra o volume de capital circulante próprio | G18: quanto menor, melhor
A19: 2023 | B19: DRE | C19: Giro do Ativo | D19: Receita Líquida/Ativo Total | E19: =DRE!C11/BP!E28 -> 0.041648715 | F19: estabelece a relação entre as vendas do período e os investimentos totais efetuados na empresa, expressando o nível de eficiência com que são utilizados os recursos aplicados, ou seja, a produtividade dos investimentos totais | G19: quanto maior, melhor
A20: 2023 | B20: DRE | C20: Margem Líquida | D20: Lucro Líquido/Receita Líquida | E20: =DRE!C15/DRE!C11 -> 0.37376908 | F20: Também conhecido como retorno sobre as vendas, apresenta o percentual de lucratividade gerado | G20: quanto maior, melhor
A21: 2023 | B21: DRE | C21: Rentabilidade ou Retorno do Ativo (ROA ou ROI) | D21: Lucro Líquido/Ativo Total | E21: =DRE!C15/BP!E28 -> 0.015567002 | F21: mede a eficiência global da alta administração na geração de lucros com seus investimentos | G21: quanto maior, melhor
A22: 2023 | B22: DRE | C22: Rentabilidade do Patrimônio Líquido ou Retorno do Capital Próprio | D22: Lucro Líquido/Patrimônio Líquido | E22: =DRE!C15/BP!E45 -> 0.19539971 | F22: apresenta o retorno que os acionistas ou quotistas da empresa estão obtendo em relação aos investimentos na empresa, ficando patente o prêmio do investidor ou proprietário pelo risco de seu empreendimento quando o indicador (taxa) obtido é superior à taxa média de juros do mercado | G22: quanto maior, melhor
A23: 2023 | B23: DRE | C23: Grau de Alavancagem Financeira | D23: Rentabilidade do Patrimônio Líquido/Rentabilidade do Ativo | E23: =E22/E21 -> 12.552174 | F23: avalia a capacidade da empresa em utilizar encargos financeiros fixos para maximizar os efeitos da variação do lucro. Determina o grau de impacto nos resultados decorrentes da utilização de capitais de terceiros | G23: quanto maior, melhor
A24: 2024 | B24: BP | C24: Liquidez Imediata | D24: Disponibilidades/PC | E24: =BP!E57/BP!E65 -> 0.0089486785 | F24: verifica a disponibilidade financeira existente no caixa ou no banco para pagamento das dívidas de curto prazo | G24: quanto maior, melhor
A25: 2024 | B25: BP | C25: Liquidez Geral | D25: (AC+ANC)/(PC+PNC) | E25: =SUM(BP!E56,BP!E60)/BP!E66 -> 1.0847101 | F25: verifica a capacidade financeira da empresa no curto e no longo prazo. | G25: quanto maior, melhor
A26: 2024 | B26: BP | C26: Liquidez Corrente ou Comum | D26: AC/PC | E26: =BP!E56/BP!E65 -> 1.0492946 | F26: verifica a capacidade financeira da empresa no curto prazo | G26: quanto maior, melhor
A27: 2024 | B27: BP | C27: Grau de Endividamento | D27: (PC+PNC)/PL | E27: =BP!E65/BP!E71 -> 11.804974 | F27: representa a relação entre o capital próprio e o capital de terceiros, ou seja, revela o quanto a empresa depende de recursos de terceiros, e isso pode influenciar diretamente na liberdade de decisão dos proprietários | G27: quanto menor, melhor
A28: 2024 | B28: BP | C28: Composição do Endividamento | D28: PC/(PC+PNC) | E28: =BP!E65/BP!E65 -> 1 | F28: através dessa análise é possível mensurar o volume de dívidas da empresa no curto prazo em relação à dívida total | G28: quanto menor, melhor
A29: 2024 | B29: BP | C29: Imobilização do Patrimônio Líquido | D29: Ativo Imobilizado/PL | E29: =BP!E62/BP!E71 -> 0.060498127 | F29: quanto mais a empresa imobiliza o seu capital próprio, mais ela dependerá de capitais de terceiros. Esse indicador mostra o volume de capital circulante próprio | G29: quanto menor, melhor
A30: 2024 | B30: DRE | C30: Giro do Ativo | D30: Receita Líquida/Ativo Total | E30: =DRE!C18/BP!E54 -> 0.042020767 | F30: estabelece a relação entre as vendas do período e os investimentos totais efetuados na empresa, expressando o nível de eficiência com que são utilizados os recursos aplicados, ou seja, a produtividade dos investimentos totais | G30: quanto maior, melhor
A31: 2024 | B31: DRE | C31: Margem Líquida | D31: Lucro Líquido/Receita Líquida | E31: =DRE!C22/DRE!C18 -> 0.34651374 | F31: Também conhecido como retorno sobre as vendas, apresenta o percentual de lucratividade gerado | G31: quanto maior, melhor
A32: 2024 | B32: DRE | C32: Rentabilidade ou Retorno do Ativo (ROA ou ROI) | D32: Lucro Líquido/Ativo Total | E32: =DRE!C22/BP!E54 -> 0.014560773 | F32: mede a eficiência global da alta administração na geração de lucros com seus investimentos | G32: quanto maior, melhor
A33: 2024 | B33: DRE | C33: Rentabilidade do Patrimônio Líquido ou Retorno do Capital Próprio | D33: Lucro Líquido/Patrimônio Líquido | E33: =DRE!C22/BP!E71 -> 0.1864504 | F33: apresenta o retorno que os acionistas ou quotistas da empresa estão obtendo em relação aos investimentos na empresa, ficando patente o prêmio do investidor ou proprietário pelo risco de seu empreendimento quando o indicador (taxa) obtido é superior à taxa média de juros do mercado | G33: quanto maior, melhor
A34: 2024 | B34: DRE | C34: Grau de Alavancagem Financeira | D34: Rentabilidade do Patrimônio Líquido/Rentabilidade do Ativo | E34: =E33/E32 -> 12.804979 | F34: avalia a capacidade da empresa em utilizar encargos financeiros fixos para maximizar os efeitos da variação do lucro. Determina o grau de impacto nos resultados decorrentes da utilização de capitais de terceiros | G34: quanto maior, melhor
